2024-09-27 06:31:31 | INFO    | __main__:stash:131 | run - {'image': '20231121', 'version': '0.10.1.post2', 'role': 'EpicPlayer', 'headless': True}
2024-09-27 06:31:42 | INFO    | __main__:claim_epic_games:97 | Try to flush cookie - {'task': 'claim_epic_games'}
2024-09-27 06:31:45 | INFO    | epic_games.agent:_login:237 | login-with-email - {'url': 'https://www.epicgames.com/id/login?lang=en-US&noHostRedirect=true&redirectUrl=https://store.epicgames.com/en-US/free-games&__cf_chl_rt_tk=oxDvCiYPnlWWtg3lFvY8fSGgEEBhXvju_IlurC2MnHM-1727389905-0.0.1.1-6633'}
2024-09-27 06:32:15 | WARNING    | epic_games.agent:authorize:266 | 执行超时 - {'task': 'authorize', 'retry': 0}
2024-09-27 06:32:17 | INFO    | epic_games.agent:_login:237 | login-with-email - {'url': 'https://www.epicgames.com/id/login?lang=en-US&noHostRedirect=true&redirectUrl=https://store.epicgames.com/en-US/free-games&__cf_chl_rt_tk=ORCT3.zDm1RGV10xS8v2FP9D3m9cv_hRxPh9zfmUa8I-1727389937-0.0.1.1-8340'}
2024-09-27 06:32:47 | WARNING    | epic_games.agent:authorize:266 | 执行超时 - {'task': 'authorize', 'retry': 1}
2024-09-27 06:32:50 | INFO    | epic_games.agent:_login:237 | login-with-email - {'url': 'https://www.epicgames.com/id/login?lang=en-US&noHostRedirect=true&redirectUrl=https://store.epicgames.com/en-US/free-games&__cf_chl_rt_tk=ikm6WbPLxr4ShIbzSixHhJSUkQfM5E5SmA8t.9wVWwk-1727389970-0.0.1.1-6548'}
2024-09-27 06:33:20 | WARNING    | epic_games.agent:authorize:266 | 执行超时 - {'task': 'authorize', 'retry': 2}
2024-09-27 06:33:20 | ERROR    | __main__:run:158 | An error has been caught in function 'run', process 'MainProcess' (3694), thread 'MainThread' (140095030442880): - {}
Traceback (most recent call last):
  File "/home/runner/work/Epic_claim/Epic_claim/epic/src/claim.py", line 162, in <module>
    asyncio.run(run())
  File "/opt/hostedtoolcache/Python/3.10.15/x64/lib/python3.10/asyncio/runners.py", line 44, in run
    return loop.run_until_complete(main)
  File "/opt/hostedtoolcache/Python/3.10.15/x64/lib/python3.10/asyncio/base_events.py", line 636, in run_until_complete
    self.run_forever()
  File "/opt/hostedtoolcache/Python/3.10.15/x64/lib/python3.10/asyncio/base_events.py", line 603, in run_forever
    self._run_once()
  File "/opt/hostedtoolcache/Python/3.10.15/x64/lib/python3.10/asyncio/base_events.py", line 1909, in _run_once
    handle._run()
  File "/opt/hostedtoolcache/Python/3.10.15/x64/lib/python3.10/asyncio/events.py", line 80, in _run
    self._context.run(self._callback, *self._args)
> File "/home/runner/work/Epic_claim/Epic_claim/epic/src/claim.py", line 158, in run
    await agent.stash()
  File "/home/runner/work/Epic_claim/Epic_claim/epic/src/claim.py", line 151, in stash
    await self.claim_epic_games(context)
  File "/home/runner/work/Epic_claim/Epic_claim/epic/src/claim.py", line 98, in claim_epic_games
    if await epic.authorize(page):
  File "/home/runner/work/Epic_claim/Epic_claim/epic/src/epic_games/agent.py", line 269, in authorize
    raise RuntimeError(f"Failed to flush token - agent={self.__class__.__name__}")
RuntimeError: Failed to flush token - agent=EpicGames
